nohup: ignoring input
üîç Loading models...
Traceback (most recent call last):
  File "/home/teja/vardhan/adp_replics/adp_env/lib/python3.8/site-packages/huggingface_hub/utils/_http.py", line 409, in hf_raise_for_status
    response.raise_for_status()
  File "/home/teja/vardhan/adp_replics/adp_env/lib/python3.8/site-packages/requests/models.py", line 1024, in raise_for_status
    raise HTTPError(http_error_msg, response=self)
requests.exceptions.HTTPError: 403 Client Error: Forbidden for url: https://huggingface.co/meta-llama/Llama-2-7b-chat-hf/resolve/main/config.json

The above exception was the direct cause of the following exception:

Traceback (most recent call last):
  File "/home/teja/vardhan/adp_replics/adp_env/lib/python3.8/site-packages/transformers/utils/hub.py", line 403, in cached_file
    resolved_file = hf_hub_download(
  File "/home/teja/vardhan/adp_replics/adp_env/lib/python3.8/site-packages/huggingface_hub/utils/_validators.py", line 114, in _inner_fn
    return fn(*args, **kwargs)
  File "/home/teja/vardhan/adp_replics/adp_env/lib/python3.8/site-packages/huggingface_hub/file_download.py", line 1008, in hf_hub_download
    return _hf_hub_download_to_cache_dir(
  File "/home/teja/vardhan/adp_replics/adp_env/lib/python3.8/site-packages/huggingface_hub/file_download.py", line 1115, in _hf_hub_download_to_cache_dir
    _raise_on_head_call_error(head_call_error, force_download, local_files_only)
  File "/home/teja/vardhan/adp_replics/adp_env/lib/python3.8/site-packages/huggingface_hub/file_download.py", line 1643, in _raise_on_head_call_error
    raise head_call_error
  File "/home/teja/vardhan/adp_replics/adp_env/lib/python3.8/site-packages/huggingface_hub/file_download.py", line 1531, in _get_metadata_or_catch_error
    metadata = get_hf_file_metadata(
  File "/home/teja/vardhan/adp_replics/adp_env/lib/python3.8/site-packages/huggingface_hub/utils/_validators.py", line 114, in _inner_fn
    return fn(*args, **kwargs)
  File "/home/teja/vardhan/adp_replics/adp_env/lib/python3.8/site-packages/huggingface_hub/file_download.py", line 1448, in get_hf_file_metadata
    r = _request_wrapper(
  File "/home/teja/vardhan/adp_replics/adp_env/lib/python3.8/site-packages/huggingface_hub/file_download.py", line 286, in _request_wrapper
    response = _request_wrapper(
  File "/home/teja/vardhan/adp_replics/adp_env/lib/python3.8/site-packages/huggingface_hub/file_download.py", line 310, in _request_wrapper
    hf_raise_for_status(response)
  File "/home/teja/vardhan/adp_replics/adp_env/lib/python3.8/site-packages/huggingface_hub/utils/_http.py", line 426, in hf_raise_for_status
    raise _format(GatedRepoError, message, response) from e
huggingface_hub.errors.GatedRepoError: 403 Client Error. (Request ID: Root=1-6840f777-46b57b5f4ce00d300c8e6af1;e984b0c3-e604-4238-8741-614e1c7e6d83)

Cannot access gated repo for url https://huggingface.co/meta-llama/Llama-2-7b-chat-hf/resolve/main/config.json.
Access to model meta-llama/Llama-2-7b-chat-hf is restricted and you are not in the authorized list. Visit https://huggingface.co/meta-llama/Llama-2-7b-chat-hf to ask for access.

The above exception was the direct cause of the following exception:

Traceback (most recent call last):
  File "vlm/my_pipe.py", line 127, in <module>
    full_pipeline(PROMPT, IMAGE_FOLDER)
  File "vlm/my_pipe.py", line 108, in full_pipeline
    llm, tokenizer = load_llm()
  File "vlm/my_pipe.py", line 96, in load_llm
    model = AutoModelForCausalLM.from_pretrained(LLM_MODEL, torch_dtype=torch.float16).to(DEVICE)
  File "/home/teja/vardhan/adp_replics/adp_env/lib/python3.8/site-packages/transformers/models/auto/auto_factory.py", line 526, in from_pretrained
    config, kwargs = AutoConfig.from_pretrained(
  File "/home/teja/vardhan/adp_replics/adp_env/lib/python3.8/site-packages/transformers/models/auto/configuration_auto.py", line 1017, in from_pretrained
    config_dict, unused_kwargs = PretrainedConfig.get_config_dict(pretrained_model_name_or_path, **kwargs)
  File "/home/teja/vardhan/adp_replics/adp_env/lib/python3.8/site-packages/transformers/configuration_utils.py", line 574, in get_config_dict
    config_dict, kwargs = cls._get_config_dict(pretrained_model_name_or_path, **kwargs)
  File "/home/teja/vardhan/adp_replics/adp_env/lib/python3.8/site-packages/transformers/configuration_utils.py", line 633, in _get_config_dict
    resolved_config_file = cached_file(
  File "/home/teja/vardhan/adp_replics/adp_env/lib/python3.8/site-packages/transformers/utils/hub.py", line 421, in cached_file
    raise EnvironmentError(
OSError: You are trying to access a gated repo.
Make sure to have access to it at https://huggingface.co/meta-llama/Llama-2-7b-chat-hf.
403 Client Error. (Request ID: Root=1-6840f777-46b57b5f4ce00d300c8e6af1;e984b0c3-e604-4238-8741-614e1c7e6d83)

Cannot access gated repo for url https://huggingface.co/meta-llama/Llama-2-7b-chat-hf/resolve/main/config.json.
Access to model meta-llama/Llama-2-7b-chat-hf is restricted and you are not in the authorized list. Visit https://huggingface.co/meta-llama/Llama-2-7b-chat-hf to ask for access.
